 You can now view your Streamlit app in your browser.

  Local URL: http://localhost:8501
  Network URL: http://192.168.1.3:8501

Exception in callback Transaction.__retry()
handle: <TimerHandle when=1014459.718 Transaction.__retry()>
Traceback (most recent call last):
  File "C:\Users\*****\miniconda3\envs\conda39\lib\asyncio\selector_events.py", line 1054, in sendto
    self._sock.sendto(data, addr)
AttributeError: 'NoneType' object has no attribute 'sendto'

During handling of the above exception, another exception occurred:

Traceback (most recent call last):
  File "C:\Users\*****\miniconda3\envs\conda39\lib\asyncio\events.py", line 80, in _run
    self._context.run(self._callback, *self._args)
  File "C:\Users\*****\miniconda3\envs\conda39\lib\site-packages\aioice\stun.py", line 312, in __retry
    self.__protocol.send_stun(self.__request, self.__addr)
  File "C:\Users\*****\miniconda3\envs\conda39\lib\site-packages\aioice\ice.py", line 266, in send_stun
    self.transport.sendto(bytes(message), addr)
  File "C:\Users\*****\miniconda3\envs\conda39\lib\asyncio\selector_events.py", line 1064, in sendto
    self._fatal_error(
  File "C:\Users\*****\miniconda3\envs\conda39\lib\asyncio\selector_events.py", line 711, in _fatal_error
    self._loop.call_exception_handler({
AttributeError: 'NoneType' object has no attribute 'call_exception_handler'
Exception in callback Transaction.__retry()
handle: <TimerHandle when=1014461.453 Transaction.__retry()>
Traceback (most recent call last):
  File "C:\Users\*****\miniconda3\envs\conda39\lib\asyncio\selector_events.py", line 1054, in sendto
    self._sock.sendto(data, addr)
AttributeError: 'NoneType' object has no attribute 'sendto'

During handling of the above exception, another exception occurred:

Traceback (most recent call last):
  File "C:\Users\*****\miniconda3\envs\conda39\lib\asyncio\events.py", line 80, in _run
    self._context.run(self._callback, *self._args)
  File "C:\Users\*****\miniconda3\envs\conda39\lib\site-packages\aioice\stun.py", line 312, in __retry
    self.__protocol.send_stun(self.__request, self.__addr)
  File "C:\Users\*****\miniconda3\envs\conda39\lib\site-packages\aioice\ice.py", line 266, in send_stun
    self.transport.sendto(bytes(message), addr)
  File "C:\Users\*****\miniconda3\envs\conda39\lib\asyncio\selector_events.py", line 1064, in sendto
    self._fatal_error(
  File "C:\Users\*****\miniconda3\envs\conda39\lib\asyncio\selector_events.py", line 711, in _fatal_error
    self._loop.call_exception_handler({
AttributeError: 'NoneType' object has no attribute 'call_exception_handler'